<sdf version='1.7'>
  <model name='husky'>
    <link name='base_link'>
      <inertial>
        <pose>-0.000634 -0.08294 0.067767 0 -0 0</pose>
        <mass>5.159</mass>
        <inertia>
          <ixx>0.61099</ixx>
          <ixy>-0.0236467</ixy>
          <ixz>-0.119719</ixz>
          <iyy>1.74651</iyy>
          <iyz>-0.00401148</iyz>
          <izz>2.03148</izz>
        </inertia>
      </inertial>
      <collision name='base_link_collision'>
        <pose>0 0 0 0 -0 0</pose>
        <geometry>
          <mesh>
            <scale>1 1 1</scale>
            <uri>package://husky_ual_description/meshes/base_link_logo.dae</uri>
          </mesh>
        </geometry>
      </collision>
      <collision name='base_link_fixed_joint_lump__lidar_link_collision_1'>
        <pose>0 0 0.3 0 -0 0</pose>
        <geometry>
          <mesh>
            <scale>1 1 1</scale>
            <uri>package://husky_ual_description/meshes/os0_32.dae</uri>
          </mesh>
        </geometry>
        <surface>
          <contact>
            <ode/>
          </contact>
          <friction>
            <ode/>
          </friction>
        </surface>
      </collision>
      <collision name='base_link_fixed_joint_lump__top_plate_link_collision_2'>
        <pose>0.0812 0 0.225 0 -0 0</pose>
        <geometry>
          <mesh>
            <scale>1 1 1</scale>
            <uri>package://husky_ual_description/meshes/large_top_plate_collision.stl</uri>
          </mesh>
        </geometry>
      </collision>
      <visual name='base_link_visual'>
        <pose>0 0 0 0 -0 0</pose>
        <geometry>
          <mesh>
            <scale>1 1 1</scale>
            <uri>package://husky_ual_description/meshes/base_link_logo.dae</uri>
          </mesh>
        </geometry>
      </visual>
      <visual name='base_link_fixed_joint_lump__front_bumper_link_visual_1'>
        <pose>0.48 0 0.091 0 -0 0</pose>
        <geometry>
          <mesh>
            <scale>1 1 1</scale>
            <uri>package://husky_description/meshes/bumper.dae</uri>
          </mesh>
        </geometry>
      </visual>
      <visual name='base_link_fixed_joint_lump__lidar_link_visual_2'>
        <pose>0 0 0.3 0 -0 0</pose>
        <geometry>
          <mesh>
            <scale>1 1 1</scale>
            <uri>package://husky_ual_description/meshes/os0_32.dae</uri>
          </mesh>
        </geometry>
      </visual>
      <visual name='base_link_fixed_joint_lump__rear_bumper_link_visual_3'>
        <pose>-0.48 0 0.091 0 0 -3.14128</pose>
        <geometry>
          <mesh>
            <scale>1 1 1</scale>
            <uri>package://husky_description/meshes/bumper.dae</uri>
          </mesh>
        </geometry>
      </visual>
      <visual name='base_link_fixed_joint_lump__top_chassis_link_visual_4'>
        <pose>0 0 0 0 -0 0</pose>
        <geometry>
          <mesh>
            <scale>1 1 1</scale>
            <uri>package://husky_description/meshes/top_chassis.dae</uri>
          </mesh>
        </geometry>
      </visual>
      <visual name='base_link_fixed_joint_lump__top_plate_link_visual_5'>
        <pose>0.0812 0 0.225 0 -0 0</pose>
        <geometry>
          <mesh>
            <scale>1 1 1</scale>
            <uri>package://husky_description/meshes/large_top_plate.dae</uri>
          </mesh>
        </geometry>
      </visual>
      <visual name='base_link_fixed_joint_lump__user_rail_link_visual_6'>
        <pose>0.272 0 0.245 0 -0 0</pose>
        <geometry>
          <mesh>
            <scale>1 1 1</scale>
            <uri>package://husky_description/meshes/user_rail.dae</uri>
          </mesh>
        </geometry>
      </visual>
      <sensor name='lidar' type='ray'>
        <always_on>1</always_on>
        <visualize>1</visualize>
        <update_rate>5</update_rate>
        <ray>
          <scan>
            <horizontal>
              <samples>720</samples>
              <resolution>1</resolution>
              <min_angle>3.6</min_angle>
              <max_angle>-3.6</max_angle>
            </horizontal>
          </scan>
          <range>
            <min>0.12</min>
            <max>15</max>
            <resolution>0.015</resolution>
          </range>
          <noise>
            <type>gaussian</type>
            <mean>0</mean>
            <stddev>0.01</stddev>
          </noise>
        </ray>
        <plugin name='scan' filename='libgazebo_ros_ray_sensor.so'>
          <ros>
            <remapping>~/out:=scan</remapping>
          </ros>
          <output_type>sensor_msgs/LaserScan</output_type>
          <frame_name>lidar_link</frame_name>
        </plugin>
        <pose>0 0 0.3 0 -0 0</pose>
      </sensor>
    </link>
    <joint name='back_left_wheel_joint' type='revolute'>
      <pose relative_to='base_link'>-0.256 0.285475 0.035 0 -0 0</pose>
      <parent>base_link</parent>
      <child>back_left_wheel</child>
      <axis>
        <xyz>0 1 0</xyz>
        <limit>
          <effort>10000</effort>
          <velocity>1000</velocity>
          <lower>-1e+16</lower>
          <upper>1e+16</upper>
        </limit>
        <dynamics>
          <spring_reference>0</spring_reference>
          <spring_stiffness>0</spring_stiffness>
        </dynamics>
      </axis>
    </joint>
    <link name='back_left_wheel'>
      <pose relative_to='back_left_wheel_joint'>0 0 0 0 -0 0</pose>
      <inertial>
        <pose>0 0 0 0 -0 0</pose>
        <mass>2.637</mass>
        <inertia>
          <ixx>0.0246688</ixx>
          <ixy>0</ixy>
          <ixz>0</ixz>
          <iyy>0.0246688</iyy>
          <iyz>0</iyz>
          <izz>0.0441058</izz>
        </inertia>
      </inertial>
      <collision name='back_left_wheel_collision'>
        <pose>0 0 0 1.5708 -0 0</pose>
        <geometry>
          <cylinder>
            <length>0.1143</length>
            <radius>0.17775</radius>
          </cylinder>
        </geometry>
      </collision>
      <visual name='back_left_wheel_visual'>
        <pose>0 0 0 0 -0 0</pose>
        <geometry>
          <mesh>
            <scale>1 1 1</scale>
            <uri>package://husky_description/meshes/wheel.dae</uri>
          </mesh>
        </geometry>
      </visual>
    </link>
    <joint name='back_right_wheel_joint' type='revolute'>
      <pose relative_to='base_link'>-0.256 -0.285475 0.035 0 -0 0</pose>
      <parent>base_link</parent>
      <child>back_right_wheel</child>
      <axis>
        <xyz>0 1 0</xyz>
        <limit>
          <effort>10000</effort>
          <velocity>1000</velocity>
          <lower>-1e+16</lower>
          <upper>1e+16</upper>
        </limit>
        <dynamics>
          <spring_reference>0</spring_reference>
          <spring_stiffness>0</spring_stiffness>
        </dynamics>
      </axis>
    </joint>
    <link name='back_right_wheel'>
      <pose relative_to='back_right_wheel_joint'>0 0 0 0 -0 0</pose>
      <inertial>
        <pose>0 0 0 0 -0 0</pose>
        <mass>2.637</mass>
        <inertia>
          <ixx>0.0246688</ixx>
          <ixy>0</ixy>
          <ixz>0</ixz>
          <iyy>0.0246688</iyy>
          <iyz>0</iyz>
          <izz>0.0441058</izz>
        </inertia>
      </inertial>
      <collision name='back_right_wheel_collision'>
        <pose>0 0 0 1.5708 -0 0</pose>
        <geometry>
          <cylinder>
            <length>0.1143</length>
            <radius>0.17775</radius>
          </cylinder>
        </geometry>
      </collision>
      <visual name='back_right_wheel_visual'>
        <pose>0 0 0 0 -0 0</pose>
        <geometry>
          <mesh>
            <scale>1 1 1</scale>
            <uri>package://husky_description/meshes/wheel.dae</uri>
          </mesh>
        </geometry>
      </visual>
    </link>
    <joint name='front_left_wheel_joint' type='revolute'>
      <pose relative_to='base_link'>0.256 0.285475 0.035 0 -0 0</pose>
      <parent>base_link</parent>
      <child>front_left_wheel</child>
      <axis>
        <xyz>0 1 0</xyz>
        <limit>
          <effort>10000</effort>
          <velocity>1000</velocity>
          <lower>-1e+16</lower>
          <upper>1e+16</upper>
        </limit>
        <dynamics>
          <spring_reference>0</spring_reference>
          <spring_stiffness>0</spring_stiffness>
        </dynamics>
      </axis>
    </joint>
    <link name='front_left_wheel'>
      <pose relative_to='front_left_wheel_joint'>0 0 0 0 -0 0</pose>
      <inertial>
        <pose>0 0 0 0 -0 0</pose>
        <mass>2.637</mass>
        <inertia>
          <ixx>0.0246688</ixx>
          <ixy>0</ixy>
          <ixz>0</ixz>
          <iyy>0.0246688</iyy>
          <iyz>0</iyz>
          <izz>0.0441058</izz>
        </inertia>
      </inertial>
      <collision name='front_left_wheel_collision'>
        <pose>0 0 0 1.5708 -0 0</pose>
        <geometry>
          <cylinder>
            <length>0.1143</length>
            <radius>0.17775</radius>
          </cylinder>
        </geometry>
      </collision>
      <visual name='front_left_wheel_visual'>
        <pose>0 0 0 0 -0 0</pose>
        <geometry>
          <mesh>
            <scale>1 1 1</scale>
            <uri>package://husky_description/meshes/wheel.dae</uri>
          </mesh>
        </geometry>
      </visual>
    </link>
    <joint name='front_right_wheel_joint' type='revolute'>
      <pose relative_to='base_link'>0.256 -0.285475 0.035 0 -0 0</pose>
      <parent>base_link</parent>
      <child>front_right_wheel</child>
      <axis>
        <xyz>0 1 0</xyz>
        <limit>
          <effort>10000</effort>
          <velocity>1000</velocity>
          <lower>-1e+16</lower>
          <upper>1e+16</upper>
        </limit>
        <dynamics>
          <spring_reference>0</spring_reference>
          <spring_stiffness>0</spring_stiffness>
        </dynamics>
      </axis>
    </joint>
    <link name='front_right_wheel'>
      <pose relative_to='front_right_wheel_joint'>0 0 0 0 -0 0</pose>
      <inertial>
        <pose>0 0 0 0 -0 0</pose>
        <mass>2.637</mass>
        <inertia>
          <ixx>0.0246688</ixx>
          <ixy>0</ixy>
          <ixz>0</ixz>
          <iyy>0.0246688</iyy>
          <iyz>0</iyz>
          <izz>0.0441058</izz>
        </inertia>
      </inertial>
      <collision name='front_right_wheel_collision'>
        <pose>0 0 0 1.5708 -0 0</pose>
        <geometry>
          <cylinder>
            <length>0.1143</length>
            <radius>0.17775</radius>
          </cylinder>
        </geometry>
      </collision>
      <visual name='front_right_wheel_visual'>
        <pose>0 0 0 0 -0 0</pose>
        <geometry>
          <mesh>
            <scale>1 1 1</scale>
            <uri>package://husky_description/meshes/wheel.dae</uri>
          </mesh>
        </geometry>
      </visual>
    </link>
    <plugin name='skid_steer_drive' filename='libgazebo_ros_diff_drive.so'>
      <update_rate>100.0</update_rate>
      <num_wheel_pairs>2</num_wheel_pairs>
      <left_joint>front_left_wheel_joint</left_joint>
      <right_joint>front_right_wheel_joint</right_joint>
      <left_joint>back_left_wheel_joint</left_joint>
      <right_joint>back_right_wheel_joint</right_joint>
      <wheel_separation>0.5709</wheel_separation>
      <wheel_diameter>0.3555</wheel_diameter>
      <robot_base_frame>base_link</robot_base_frame>
      <max_wheel_torque>35</max_wheel_torque>
      <max_wheel_acceleration>5.0</max_wheel_acceleration>
      <ros>
        <remapping>cmd_vel:=cmd_vel</remapping>
        <remapping>odom:=odom</remapping>
      </ros>
      <publish_odom>1</publish_odom>
      <publish_odom_tf>1</publish_odom_tf>
      <publish_wheel_tf>1</publish_wheel_tf>
      <odometry_frame>odom</odometry_frame>
    </plugin>
  </model>
</sdf>
